[2025-04-10T02:25:36.218+0000] {taskinstance.py:1159} INFO - Dependencies all met for dep_context=non-requeueable deps ti=<TaskInstance: etl_pipeline.extract_data manual__2025-04-10T02:25:34.400828+00:00 [queued]>
[2025-04-10T02:25:36.232+0000] {taskinstance.py:1159} INFO - Dependencies all met for dep_context=requeueable deps ti=<TaskInstance: etl_pipeline.extract_data manual__2025-04-10T02:25:34.400828+00:00 [queued]>
[2025-04-10T02:25:36.233+0000] {taskinstance.py:1361} INFO - Starting attempt 1 of 1
[2025-04-10T02:25:36.316+0000] {taskinstance.py:1382} INFO - Executing <Task(PythonOperator): extract_data> on 2025-04-10 02:25:34.400828+00:00
[2025-04-10T02:25:36.325+0000] {standard_task_runner.py:57} INFO - Started process 316 to run task
[2025-04-10T02:25:36.328+0000] {standard_task_runner.py:84} INFO - Running: ['***', 'tasks', 'run', 'etl_pipeline', 'extract_data', 'manual__2025-04-10T02:25:34.400828+00:00', '--job-id', '10', '--raw', '--subdir', 'DAGS_FOLDER/etl_pipeline_dag.py', '--cfg-path', '/tmp/tmp0zz8fue4']
[2025-04-10T02:25:36.351+0000] {standard_task_runner.py:85} INFO - Job 10: Subtask extract_data
[2025-04-10T02:25:36.484+0000] {task_command.py:416} INFO - Running <TaskInstance: etl_pipeline.extract_data manual__2025-04-10T02:25:34.400828+00:00 [running]> on host 199c3751bd8a
[2025-04-10T02:25:36.671+0000] {taskinstance.py:1662} INFO - Exporting env vars: AIRFLOW_CTX_DAG_OWNER='***' AIRFLOW_CTX_DAG_ID='etl_pipeline' AIRFLOW_CTX_TASK_ID='extract_data' AIRFLOW_CTX_EXECUTION_DATE='2025-04-10T02:25:34.400828+00:00' AIRFLOW_CTX_TRY_NUMBER='1' AIRFLOW_CTX_DAG_RUN_ID='manual__2025-04-10T02:25:34.400828+00:00'
[2025-04-10T02:25:36.674+0000] {taskinstance.py:1937} ERROR - Task failed with exception
Traceback (most recent call last):
  File "/home/airflow/.local/lib/python3.9/site-packages/airflow/operators/python.py", line 192, in execute
    return_value = self.execute_callable()
  File "/home/airflow/.local/lib/python3.9/site-packages/airflow/operators/python.py", line 209, in execute_callable
    return self.python_callable(*self.op_args, **self.op_kwargs)
  File "/opt/airflow/dags/etl_pipeline_dag.py", line 13, in extract
    df = pd.read_csv(CSV_PATH)
  File "/home/airflow/.local/lib/python3.9/site-packages/pandas/io/parsers/readers.py", line 948, in read_csv
    return _read(filepath_or_buffer, kwds)
  File "/home/airflow/.local/lib/python3.9/site-packages/pandas/io/parsers/readers.py", line 611, in _read
    parser = TextFileReader(filepath_or_buffer, **kwds)
  File "/home/airflow/.local/lib/python3.9/site-packages/pandas/io/parsers/readers.py", line 1448, in __init__
    self._engine = self._make_engine(f, self.engine)
  File "/home/airflow/.local/lib/python3.9/site-packages/pandas/io/parsers/readers.py", line 1705, in _make_engine
    self.handles = get_handle(
  File "/home/airflow/.local/lib/python3.9/site-packages/pandas/io/common.py", line 863, in get_handle
    handle = open(
FileNotFoundError: [Errno 2] No such file or directory: '/opt/airflow/datasets/df_limpio.csv'
[2025-04-10T02:25:36.684+0000] {taskinstance.py:1400} INFO - Marking task as FAILED. dag_id=etl_pipeline, task_id=extract_data, execution_date=20250410T022534, start_date=20250410T022536, end_date=20250410T022536
[2025-04-10T02:25:36.727+0000] {standard_task_runner.py:104} ERROR - Failed to execute job 10 for task extract_data ([Errno 2] No such file or directory: '/opt/airflow/datasets/df_limpio.csv'; 316)
[2025-04-10T02:25:36.778+0000] {local_task_job_runner.py:228} INFO - Task exited with return code 1
[2025-04-10T02:25:36.804+0000] {taskinstance.py:2778} INFO - 0 downstream tasks scheduled from follow-on schedule check
