[2025-04-10T04:18:56.199+0000] {taskinstance.py:1159} INFO - Dependencies all met for dep_context=non-requeueable deps ti=<TaskInstance: etl_pipeline_dag.extract_csv_to_parquet manual__2025-04-10T04:18:54.761551+00:00 [queued]>
[2025-04-10T04:18:56.210+0000] {taskinstance.py:1159} INFO - Dependencies all met for dep_context=requeueable deps ti=<TaskInstance: etl_pipeline_dag.extract_csv_to_parquet manual__2025-04-10T04:18:54.761551+00:00 [queued]>
[2025-04-10T04:18:56.210+0000] {taskinstance.py:1361} INFO - Starting attempt 1 of 2
[2025-04-10T04:18:56.267+0000] {taskinstance.py:1382} INFO - Executing <Task(PythonOperator): extract_csv_to_parquet> on 2025-04-10 04:18:54.761551+00:00
[2025-04-10T04:18:56.276+0000] {standard_task_runner.py:57} INFO - Started process 256 to run task
[2025-04-10T04:18:56.279+0000] {standard_task_runner.py:84} INFO - Running: ['***', 'tasks', 'run', 'etl_pipeline_dag', 'extract_csv_to_parquet', 'manual__2025-04-10T04:18:54.761551+00:00', '--job-id', '23', '--raw', '--subdir', 'DAGS_FOLDER/etl_pipeline_dag.py', '--cfg-path', '/tmp/tmpaum3o8oy']
[2025-04-10T04:18:56.281+0000] {standard_task_runner.py:85} INFO - Job 23: Subtask extract_csv_to_parquet
[2025-04-10T04:18:54.355+0000] {task_command.py:416} INFO - Running <TaskInstance: etl_pipeline_dag.extract_csv_to_parquet manual__2025-04-10T04:18:54.761551+00:00 [running]> on host e0439407d4c2
[2025-04-10T04:18:54.611+0000] {taskinstance.py:1662} INFO - Exporting env vars: AIRFLOW_CTX_DAG_OWNER='sim√≥n' AIRFLOW_CTX_DAG_ID='etl_pipeline_dag' AIRFLOW_CTX_TASK_ID='extract_csv_to_parquet' AIRFLOW_CTX_EXECUTION_DATE='2025-04-10T04:18:54.761551+00:00' AIRFLOW_CTX_TRY_NUMBER='1' AIRFLOW_CTX_DAG_RUN_ID='manual__2025-04-10T04:18:54.761551+00:00'
[2025-04-10T04:18:54.614+0000] {taskinstance.py:1937} ERROR - Task failed with exception
Traceback (most recent call last):
  File "/home/airflow/.local/lib/python3.9/site-packages/airflow/operators/python.py", line 192, in execute
    return_value = self.execute_callable()
  File "/home/airflow/.local/lib/python3.9/site-packages/airflow/operators/python.py", line 209, in execute_callable
    return self.python_callable(*self.op_args, **self.op_kwargs)
  File "/opt/airflow/dags/etl_pipeline_dag.py", line 14, in extract_csv_to_parquet
    df = pd.read_csv(input_path)
  File "/home/airflow/.local/lib/python3.9/site-packages/pandas/io/parsers/readers.py", line 948, in read_csv
    return _read(filepath_or_buffer, kwds)
  File "/home/airflow/.local/lib/python3.9/site-packages/pandas/io/parsers/readers.py", line 611, in _read
    parser = TextFileReader(filepath_or_buffer, **kwds)
  File "/home/airflow/.local/lib/python3.9/site-packages/pandas/io/parsers/readers.py", line 1448, in __init__
    self._engine = self._make_engine(f, self.engine)
  File "/home/airflow/.local/lib/python3.9/site-packages/pandas/io/parsers/readers.py", line 1705, in _make_engine
    self.handles = get_handle(
  File "/home/airflow/.local/lib/python3.9/site-packages/pandas/io/common.py", line 863, in get_handle
    handle = open(
FileNotFoundError: [Errno 2] No such file or directory: '/opt/airflow/data/df_limpio.csv'
[2025-04-10T04:18:54.626+0000] {taskinstance.py:1400} INFO - Marking task as UP_FOR_RETRY. dag_id=etl_pipeline_dag, task_id=extract_csv_to_parquet, execution_date=20250410T041854, start_date=20250410T041856, end_date=20250410T041854
[2025-04-10T04:18:54.706+0000] {standard_task_runner.py:104} ERROR - Failed to execute job 23 for task extract_csv_to_parquet ([Errno 2] No such file or directory: '/opt/airflow/data/df_limpio.csv'; 256)
[2025-04-10T04:18:54.751+0000] {local_task_job_runner.py:228} INFO - Task exited with return code 1
[2025-04-10T04:18:54.779+0000] {taskinstance.py:2778} INFO - 0 downstream tasks scheduled from follow-on schedule check
